<sdf version='1.6'>
  <model name='myboat'>
    <link name='footplate'>
      <pose frame=''>-2.5 0 0.2 0 -0 0</pose>
      <inertial>
        <pose frame=''>0 0 0 0 -0 0</pose>
        <mass>0.1</mass>
        <inertia>
          <ixx>0.0008</ixx>
          <ixy>0</ixy>
          <ixz>0</ixz>
          <iyy>0.000166</iyy>
          <iyz>0</iyz>
          <izz>0.0008</izz>
        </inertia>
      </inertial>
      <collision name='footplate_collision'>
        <pose frame=''>0 0 0 0 -0 0</pose>
        <geometry>
          <box>
            <size>0.1 0.3 0.1</size>
          </box>
        </geometry>
      </collision>
      <visual name='footplate_visual'>
        <pose frame=''>0 0 0 0 -0 0</pose>
        <geometry>
          <box>
            <size>0.1 0.3 0.1</size>
          </box>
        </geometry>
      </visual>
    </link>
    <joint name='sk_fp' type='fixed'>
      <child>footplate</child>
      <parent>world</parent>
    </joint>
    <link name='lowerleg'>
      <pose frame=''>-2.5 0 0.2 0 0.100168 0</pose>
      <inertial>
        <pose frame=''>-0.25 0 0 0 -0 0</pose>
        <mass>1</mass>
        <inertia>
          <ixx>0.001</ixx>
          <ixy>0</ixy>
          <ixz>0</ixz>
          <iyy>0.0005</iyy>
          <iyz>0</iyz>
          <izz>0.001</izz>
        </inertia>
      </inertial>
      <collision name='lowerleg_collision'>
        <pose frame=''>-0.25 0 0 0 -0 0</pose>
        <geometry>
          <box>
            <size>0.5 0.05 0.05</size>
          </box>
        </geometry>
      </collision>
      <visual name='lowerleg_visual'>
        <pose frame=''>-0.25 0 0 0 -0 0</pose>
        <geometry>
          <box>
            <size>0.5 0.05 0.05</size>
          </box>
        </geometry>
      </visual>
    </link>
    <joint name='fp_ll' type='revolute'>
      <child>lowerleg</child>
      <parent>footplate</parent>
      <axis>
        <xyz>0 1 0</xyz>
        <limit>
          <lower>0</lower>
          <upper>1.5708</upper>
          <effort>1000</effort>
          <velocity>1</velocity>
        </limit>
        <dynamics>
          <damping>0.005</damping>
          <friction>0</friction>
          <spring_reference>0</spring_reference>
          <spring_stiffness>0</spring_stiffness>
        </dynamics>
        <use_parent_model_frame>1</use_parent_model_frame>
      </axis>
    </joint>
    <link name='upperleg_1'>
      <pose frame=''>-2.99749 0 0.25 0 0.100168 0</pose>
      <inertial>
        <pose frame=''>-0.125 0 0 0 -0 0</pose>
        <mass>1</mass>
        <inertia>
          <ixx>0.001</ixx>
          <ixy>0</ixy>
          <ixz>0</ixz>
          <iyy>0.0005</iyy>
          <iyz>0</iyz>
          <izz>0.001</izz>
        </inertia>
      </inertial>
      <collision name='upperleg_1_collision'>
        <pose frame=''>-0.125 0 0 0 -0 0</pose>
        <geometry>
          <box>
            <size>0.25 0.05 0.05</size>
          </box>
        </geometry>
      </collision>
      <visual name='upperleg_1_visual'>
        <pose frame=''>-0.125 0 0 0 -0 0</pose>
        <geometry>
          <box>
            <size>0.25 0.05 0.05</size>
          </box>
        </geometry>
      </visual>
    </link>
    <joint name='knee' type='revolute'>
      <child>upperleg_1</child>
      <parent>lowerleg</parent>
      <axis>
        <xyz>0 1 0</xyz>
        <limit>
          <lower>-3.1</lower>
          <upper>0</upper>
          <effort>100</effort>
          <velocity>1</velocity>
        </limit>
        <dynamics>
          <damping>0.005</damping>
          <friction>0</friction>
          <spring_reference>0</spring_reference>
          <spring_stiffness>0</spring_stiffness>
        </dynamics>
        <use_parent_model_frame>1</use_parent_model_frame>
      </axis>
    </joint>
    <link name='seat'>
      <pose frame=''>-3.49514 0 0.2 0 -0 0</pose>
      <inertial>
        <pose frame=''>0 0 0 0 -0 0</pose>
        <mass>0.1</mass>
        <inertia>
          <ixx>0.001</ixx>
          <ixy>0</ixy>
          <ixz>0</ixz>
          <iyy>0.0005</iyy>
          <iyz>0</iyz>
          <izz>0.001</izz>
        </inertia>
      </inertial>
      <collision name='seat_collision'>
        <pose frame=''>0 0 0 0 -0 0</pose>
        <geometry>
          <box>
            <size>0.1 0.3 0.1</size>
          </box>
        </geometry>
      </collision>
      <visual name='seat_visual'>
        <pose frame=''>0 0 0 0 -0 0</pose>
        <geometry>
          <box>
            <size>0.1 0.3 0.1</size>
          </box>
        </geometry>
      </visual>
    </link>
    <joint name='sliding' type='prismatic'>
      <child>seat</child>
      <parent>world</parent>
      <axis>
        <xyz>1 0 0</xyz>
        <limit>
          <lower>-0.1</lower>
          <upper>0.8</upper>
          <effort>1000</effort>
          <velocity>0.5</velocity>
        </limit>
        <dynamics>
          <damping>0.005</damping>
          <friction>0</friction>
          <spring_reference>0</spring_reference>
          <spring_stiffness>0</spring_stiffness>
        </dynamics>
        <use_parent_model_frame>1</use_parent_model_frame>
      </axis>
    </joint>
    <link name='upperleg_2'>
      <pose frame=''>-3.49514 0 0.3 0 0.100168 0</pose>
      <inertial>
        <pose frame=''>0.125 0 0 0 -0 0</pose>
        <mass>1</mass>
        <inertia>
          <ixx>0.001</ixx>
          <ixy>0</ixy>
          <ixz>0</ixz>
          <iyy>0.0005</iyy>
          <iyz>0</iyz>
          <izz>0.001</izz>
        </inertia>
      </inertial>
      <collision name='upperleg_2_collision'>
        <pose frame=''>0.125 0 0 0 -0 0</pose>
        <geometry>
          <box>
            <size>0.25 0.05 0.05</size>
          </box>
        </geometry>
      </collision>
      <visual name='upperleg_2_visual'>
        <pose frame=''>0.125 0 0 0 -0 0</pose>
        <geometry>
          <box>
            <size>0.25 0.05 0.05</size>
          </box>
        </geometry>
      </visual>
    </link>
    <joint name='hip1' type='revolute'>
      <child>upperleg_2</child>
      <parent>seat</parent>
      <axis>
        <xyz>0 1 0</xyz>
        <limit>
          <lower>-1.6</lower>
          <upper>0</upper>
          <effort>100</effort>
          <velocity>1</velocity>
        </limit>
        <dynamics>
          <damping>0.005</damping>
          <friction>0</friction>
          <spring_reference>0</spring_reference>
          <spring_stiffness>0</spring_stiffness>
        </dynamics>
        <use_parent_model_frame>1</use_parent_model_frame>
      </axis>
    </joint>
    <link name='back_low'>
      <pose frame=''>-3.49514 0 0.3 3.14159 -1.2308 3.14159</pose>
      <inertial>
        <pose frame=''>0.15 0 0 0 -0 0</pose>
        <mass>10</mass>
        <inertia>
          <ixx>0.01</ixx>
          <ixy>0</ixy>
          <ixz>0</ixz>
          <iyy>0.077</iyy>
          <iyz>0</iyz>
          <izz>0.083</izz>
        </inertia>
      </inertial>
      <collision name='back_low_collision'>
        <pose frame=''>0.15 0 0 0 -0 0</pose>
        <geometry>
          <box>
            <size>0.3 0.1 0.05</size>
          </box>
        </geometry>
      </collision>
      <visual name='back_low_visual'>
        <pose frame=''>0.15 0 0 0 -0 0</pose>
        <geometry>
          <box>
            <size>0.3 0.1 0.05</size>
          </box>
        </geometry>
      </visual>
    </link>
    <joint name='hip2' type='revolute'>
      <child>back_low</child>
      <parent>seat</parent>
      <axis>
        <xyz>0 1 0</xyz>
        <limit>
          <lower>-1</lower>
          <upper>1</upper>
          <effort>100</effort>
          <velocity>1</velocity>
        </limit>
        <dynamics>
          <damping>0.005</damping>
          <friction>0</friction>
          <spring_reference>0</spring_reference>
          <spring_stiffness>0</spring_stiffness>
        </dynamics>
        <use_parent_model_frame>1</use_parent_model_frame>
      </axis>
    </joint>
    <link name='back_high'>
      <pose frame=''>-3.59519 0 0.582826 3.14159 -1.2308 3.14159</pose>
      <inertial>
        <pose frame=''>0.163636 0 0 0 -0 0</pose>
        <mass>11</mass>
        <inertia>
          <ixx>0.033</ixx>
          <ixy>0</ixy>
          <ixz>0</ixz>
          <iyy>0.0978545</iyy>
          <iyz>0</iyz>
          <izz>0.127455</izz>
        </inertia>
      </inertial>
      <collision name='back_high_collision'>
        <pose frame=''>0.15 0 0 0 -0 0</pose>
        <geometry>
          <box>
            <size>0.3 0.15 0.05</size>
          </box>
        </geometry>
      </collision>
      <visual name='back_high_visual'>
        <pose frame=''>0.15 0 0 0 -0 0</pose>
        <geometry>
          <box>
            <size>0.3 0.15 0.05</size>
          </box>
        </geometry>
      </visual>
      <visual name='back_high_fixed_joint_lump__shoulder_link_visual_1'>
        <pose frame=''>0.3 0 0 0 -0 0</pose>
        <geometry>
          <box>
            <size>0.05 0.4 0.05</size>
          </box>
        </geometry>
      </visual>
    </link>
    <joint name='back_lh' type='revolute'>
      <child>back_high</child>
      <parent>back_low</parent>
      <axis>
        <xyz>0 1 0</xyz>
        <limit>
          <lower>0</lower>
          <upper>0.5</upper>
          <effort>100</effort>
          <velocity>1</velocity>
        </limit>
        <dynamics>
          <damping>0.005</damping>
          <friction>0</friction>
          <spring_reference>0</spring_reference>
          <spring_stiffness>0</spring_stiffness>
        </dynamics>
        <use_parent_model_frame>1</use_parent_model_frame>
      </axis>
    </joint>
    <link name='left_shoulder_xx_link'>
      <pose frame=''>-3.69523 0.2 0.865653 -2.79032 -1.20769 2.76797</pose>
      <inertial>
        <pose frame=''>0 0 0 0 -0 0</pose>
        <mass>0.02</mass>
        <inertia>
          <ixx>3.34e-07</ixx>
          <ixy>0</ixy>
          <ixz>0</ixz>
          <iyy>3.34e-07</iyy>
          <iyz>0</iyz>
          <izz>3.34e-07</izz>
        </inertia>
      </inertial>
      <visual name='left_shoulder_xx_link_visual'>
        <pose frame=''>0 0 0 0 -0 0</pose>
        <geometry>
          <box>
            <size>0.01 0.01 0.01</size>
          </box>
        </geometry>
      </visual>
      <visual name='left_shoulder_xx_link_fixed_joint_lump__left_shoulder_psi_link_visual_1'>
        <pose frame=''>0 0 0 -0.803 0 0</pose>
        <geometry>
          <box>
            <size>0.01 0.01 0.01</size>
          </box>
        </geometry>
      </visual>
    </link>
    <joint name='shoulder_l' type='revolute'>
      <child>left_shoulder_xx_link</child>
      <parent>back_high</parent>
      <axis>
        <xyz>-0.942755 0 -0.333487</xyz>
        <limit>
          <lower>-1.5</lower>
          <upper>0.5</upper>
          <effort>100</effort>
          <velocity>1</velocity>
        </limit>
        <dynamics>
          <damping>0.005</damping>
          <friction>0</friction>
          <spring_reference>0</spring_reference>
          <spring_stiffness>0</spring_stiffness>
        </dynamics>
        <use_parent_model_frame>1</use_parent_model_frame>
      </axis>
    </joint>
    <link name='arm_l_upper'>
      <pose frame=''>-3.69523 0.2 0.865653 0.42859 -1.18849 -1.20039</pose>
      <inertial>
        <pose frame=''>-0.245218 0.004538 -0.046902 0 -0 0</pose>
        <mass>2.02</mass>
        <inertia>
          <ixx>0.0116713</ixx>
          <ixy>0.000524506</ixy>
          <ixz>-0.00542045</ixz>
          <iyy>0.0277945</iyy>
          <iyz>0.00069704</iyz>
          <izz>0.0206585</izz>
        </inertia>
      </inertial>
      <visual name='arm_l_upper_visual'>
        <pose frame=''>-0.175 0 0 0 -0 0</pose>
        <geometry>
          <box>
            <size>0.35 0.05 0.05</size>
          </box>
        </geometry>
      </visual>
      <visual name='arm_l_upper_fixed_joint_lump__left_elbow_psi_link_visual_1'>
        <pose frame=''>-0.35 0 0 3.14159 -1.20159 3.14159</pose>
        <geometry>
          <box>
            <size>0.01 0.01 0.01</size>
          </box>
        </geometry>
      </visual>
      <visual name='arm_l_upper_fixed_joint_lump__arm_l_lower_1_visual_2'>
        <pose frame=''>-0.314059 0.008988 -0.092884 2.91336 -1.19127 -2.89655</pose>
        <geometry>
          <box>
            <size>0.2 0.05 0.05</size>
          </box>
        </geometry>
      </visual>
      <visual name='arm_l_upper_fixed_joint_lump__dummy_link_1_visual_3'>
        <pose frame=''>-0.278118 0.017976 -0.185768 2.91336 -1.19127 -2.89655</pose>
        <geometry>
          <box>
            <size>0.01 0.01 0.01</size>
          </box>
        </geometry>
      </visual>
    </link>
    <joint name='LShoulderTheta' type='revolute'>
      <child>arm_l_upper</child>
      <parent>left_shoulder_xx_link</parent>
      <axis>
        <xyz>0.708285 0.688691 0.155042</xyz>
        <limit>
          <lower>-2</lower>
          <upper>1</upper>
          <effort>100</effort>
          <velocity>1</velocity>
        </limit>
        <dynamics>
          <damping>0.005</damping>
          <friction>0</friction>
          <spring_reference>0</spring_reference>
          <spring_stiffness>0</spring_stiffness>
        </dynamics>
        <use_parent_model_frame>1</use_parent_model_frame>
      </axis>
    </joint>
    <self_collide>1</self_collide>
    <static>0</static>
    <joint name='lower12' type='fixed'>
      <pose frame=''>0.25 0 0 0 -0 0</pose>
      <parent>upperleg_1</parent>
      <child>upperleg_2</child>
    </joint>
  </model>
</sdf>
