<?xml version="1.0" encoding="utf-8"?>
<!-- =================================================================================== -->
<!-- |    This document was autogenerated by xacro from boot.xacro                     | -->
<!-- |    EDITING THIS FILE BY HAND IS NOT RECOMMENDED                                 | -->
<!-- =================================================================================== -->
<robot name="myboat" xmlns:xacro="http://www.ros.org/wiki/xacro">
  <!-- Constants for robot dimensions -->
  <gazebo>
    <self_collide>1</self_collide>
  </gazebo>
  <!-- ros_control plugin -->
  <gazebo>
    <plugin filename="libgazebo_ros_control.so" name="gazebo_ros_control">
      <robotNamespace>/boot</robotNamespace>
      <robotSimType>gazebo_ros_control/DefaultRobotHWSim</robotSimType>
    </plugin>
    <!--
  <plugin name="sb_rl_sensor" filename="libgazebo_ros_ft_sensor.so">
    <updateRate>50.0</updateRate>
    <topicName>sb_rl_sensor</topicName>
    <jointName>starboard_rowlock</jointName>
  </plugin>

  <plugin name="p_rl_sensor" filename="libgazebo_ros_ft_sensor.so">
    <updateRate>50.0</updateRate>
    <topicName>p_rl_sensor</topicName>
    <jointName>port_rowlock</jointName>
  </plugin>

  <plugin name="sb_oar_sensor" filename="libgazebo_ros_ft_sensor.so">
    <updateRate>50.0</updateRate>
    <topicName>sb_oar_sensor</topicName>
    <jointName>starboard_oar</jointName>
  </plugin>

  <plugin name="p_oar_sensor" filename="libgazebo_ros_ft_sensor.so">
    <updateRate>50.0</updateRate>
    <topicName>p_oar_sensor</topicName>
    <jointName>port_oar</jointName>
    <noise>
      <type>gaussian</type>
      <mean>0.0</mean>
      <stddev>0.003</stddev>
    </noise>
  </plugin>

  <plugin name="sbb_sensor" filename="libgazebo_ros_ft_sensor.so">
    <updateRate>50.0</updateRate>
    <topicName>sbb_sensor</topicName>
    <jointName>starboard_blade</jointName>
  </plugin>

  <plugin name="pb_sensor" filename="libgazebo_ros_ft_sensor.so">
    <updateRate>50.0</updateRate>
    <topicName>pb_sensor</topicName>
    <jointName>port_blade</jointName>
  </plugin>
  -->
  </gazebo>
  <gazebo reference="starboard_rowlock">
    <provideFeedback>true</provideFeedback>
  </gazebo>
  <gazebo reference="port_rowlock">
    <provideFeedback>true</provideFeedback>
  </gazebo>
  <gazebo reference="starboard_oar">
    <provideFeedback>true</provideFeedback>
  </gazebo>
  <gazebo reference="port_oar">
    <provideFeedback>true</provideFeedback>
  </gazebo>
  <gazebo reference="starboard_blade">
    <provideFeedback>true</provideFeedback>
  </gazebo>
  <gazebo reference="port_blade">
    <provideFeedback>true</provideFeedback>
  </gazebo>
  <gazebo reference="skiff">
    <material>Gazebo/White</material>
    <mu1>0.01</mu1>
    <mu2>0.01</mu2>
    <collision>
      <surface>
        <friction>
          <ode>
            <slip1>0.05</slip1>
            <slip2>0.12</slip2>
          </ode>
        </friction>
      </surface>
    </collision>
  </gazebo>
  <gazebo reference="starboard_rowlock_l">
    <mu1>0.01</mu1>
    <mu2>0.01</mu2>
    <material>Gazebo/Green</material>
  </gazebo>
  <gazebo reference="port_rowlock_l">
    <mu1>0.01</mu1>
    <mu2>0.01</mu2>
    <material>Gazebo/Red</material>
    <provideFeedback>true</provideFeedback>
  </gazebo>
  <gazebo reference="starboard_oar_l">
    <mu1>0.01</mu1>
    <mu2>0.01</mu2>
    <material>Gazebo/Green</material>
    <provideFeedback>true</provideFeedback>
  </gazebo>
  <gazebo reference="port_oar_l">
    <mu1>0.01</mu1>
    <mu2>0.01</mu2>
    <material>Gazebo/Green</material>
    <provideFeedback>true</provideFeedback>
  </gazebo>
  <gazebo reference="starboard_blade_l">
    <mu1>10.0</mu1>
    <mu2>10.0</mu2>
    <material>Gazebo/Green</material>
    <provideFeedback>true</provideFeedback>
  </gazebo>
  <gazebo reference="port_blade_l">
    <mu1>10.0</mu1>
    <mu2>10.0</mu2>
    <material>Gazebo/Red</material>
    <provideFeedback>true</provideFeedback>
  </gazebo>
  <gazebo reference="voetenboord">
    <material>Gazebo/Gray</material>
  </gazebo>
  <gazebo>
    <joint name="lower12" type="fixed">
      <pose>0.25 0.0 0 0 0 0.0</pose>
      <parent>upperleg_1</parent>
      <child>upperleg_2</child>
    </joint>
    <!--
  <joint name="lowerarm_left" type="fixed">
    <pose>0.0 0.0 0 0 0 0.1</pose>
    <parent>dummy_link_1</parent>
    <child>dummy_link_2</child>
  </joint>
-->
  </gazebo>
  <material name="black">
    <color rgba="0.0 0.0 0.0 1.0"/>
  </material>
  <material name="blue">
    <color rgba="0.0 0.0 0.8 1.0"/>
  </material>
  <material name="green">
    <color rgba="0.0 0.8 0.0 1.0"/>
  </material>
  <material name="grey">
    <color rgba="0.2 0.2 0.2 1.0"/>
  </material>
  <material name="orange">
    <color rgba="1.0 0.423529411765 0.0392156862745 1.0"/>
  </material>
  <material name="brown">
    <color rgba="0.870588235294 0.811764705882 0.764705882353 1.0"/>
  </material>
  <material name="red">
    <color rgba="0.8 0.0 0.0 1.0"/>
  </material>
  <material name="white">
    <color rgba="1.0 1.0 1.0 1.0"/>
  </material>
  <!--
    Describes parameters of the boot model
-->
  <!--
 lengths of links, musle power?
-->
  <!-- Rower joints -->
  <joint name="sk_fp" type="fixed">
    <parent link="world"/>
    <child link="footplate"/>
    <origin rpy="0.0  0 0.0" xyz="-2.5 0.0  0.2"/>
    <dynamics damping="0.005"/>
    <limit effort="101.0" lower="-0.4" upper="0.4" velocity="1.0"/>
  </joint>
  <joint name="sliding" type="prismatic">
    <parent link="world"/>
    <child link="seat"/>
    <origin rpy="0 0 0" xyz="-3.49514 0.0 0.2"/>
    <dynamics damping="0.005"/>
    <axis xyz="1 0 0"/>
    <limit effort="1000.0" lower="-0.1" upper="0.8" velocity="0.5"/>
  </joint>
  <joint name="fp_ll" type="revolute">
    <parent link="footplate"/>
    <child link="lowerleg"/>
    <origin rpy="0.0  0.1001675 0.0" xyz="0.0 0.0   0.0"/>
    <dynamics damping="0.005"/>
    <axis xyz="0 1 0"/>
    <limit effort="1000.0" lower="0.0" upper="1.57079632679" velocity="1.0"/>
  </joint>
  <joint name="knee" type="revolute">
    <parent link="lowerleg"/>
    <child link="upperleg_1"/>
    <origin rpy="0.0  0 0.0" xyz="-0.5 0.0   0.0"/>
    <dynamics damping="0.005"/>
    <axis xyz="0 1 0"/>
    <limit effort="100.0" lower="-3.1" upper="0" velocity="1.0"/>
  </joint>
  <joint name="hip1" type="revolute">
    <parent link="seat"/>
    <child link="upperleg_2"/>
    <origin rpy="0  0.1001675 0.0" xyz="0.0 0.0   0.1"/>
    <dynamics damping="0.005"/>
    <axis xyz="0 1 0"/>
    <limit effort="100.0" lower="-1.6" upper="0" velocity="1.0"/>
  </joint>
  <joint name="hip2" type="revolute">
    <parent link="seat"/>
    <child link="back_low"/>
    <origin rpy="0  -1.91079632679 0.0" xyz="0.0 0.0   0.1"/>
    <dynamics damping="0.005"/>
    <axis xyz="0 1 0"/>
    <limit effort="100.0" lower="-1.0" upper="1.0" velocity="1.0"/>
  </joint>
  <joint name="back_lh" type="revolute">
    <parent link="back_low"/>
    <child link="back_high"/>
    <origin rpy="0  0.0 0.0" xyz="0.3 0.0   0.0"/>
    <dynamics damping="0.005"/>
    <axis xyz="0 1 0"/>
    <limit effort="100.0" lower="0.0" upper="0.5" velocity="1.0"/>
  </joint>
  <joint name="shoulder" type="fixed">
    <parent link="back_high"/>
    <child link="shoulder_link"/>
    <origin rpy="0  0.0 0.0" xyz="0.3 0.0   0.0"/>
    <dynamics damping="0.005"/>
    <limit effort="101.0" lower="0.0" upper="0.5" velocity="1.0"/>
  </joint>
  <!-- 3D joint left shoulder -->
  <joint name="shoulder_l" type="revolute">
    <parent link="shoulder_link"/>
    <child link="left_shoulder_xx_link"/>
    <origin rpy="0.0 0.0 0.13" xyz="0.0 0.2   0.0"/>
    <axis xyz="0 0 1"/>
    <dynamics damping="0.005"/>
    <limit effort="100.0" lower="-1.5" upper="0.5" velocity="1.0"/>
  </joint>
  <link name="left_shoulder_xx_link">
    <inertial>
      <mass value="0.01"/>
      <origin rpy="0 0 0" xyz="0 0.0 0.0"/>
      <inertia ixx="0.000000167" ixy="0" ixz="0" iyy="0.000000167" iyz="0" izz="0.000000167"/>
    </inertial>
    <visual>
      <origin rpy="0 0 0" xyz="0.0 0.0 0.0"/>
      <geometry>
        <box size="0.01 0.01 0.01"/>
      </geometry>
    </visual>
  </link>
  <joint name="shoulder_iets" type="fixed">
    <parent link="left_shoulder_xx_link"/>
    <child link="left_shoulder_psi_link"/>
    <origin rpy="-0.803 0.0 0.0" xyz="0.0 0.0   0.0"/>
    <axis xyz="1 0 0"/>
    <dynamics damping="0.005"/>
    <limit effort="100.0" lower="-1.5" upper="1.5" velocity="1.0"/>
  </joint>
  <link name="left_shoulder_psi_link">
    <inertial>
      <mass value="0.01"/>
      <origin rpy="0 0 0" xyz="0 0.0 0.0"/>
      <inertia ixx="0.000000167" ixy="0" ixz="0" iyy="0.000000167" iyz="0" izz="0.000000167"/>
    </inertial>
    <visual>
      <origin rpy="0 0 0" xyz="0.0 0.0 0.0"/>
      <geometry>
        <box size="0.01 0.01 0.01"/>
      </geometry>
    </visual>
  </link>
  <joint name="LShoulderTheta" type="revolute">
    <parent link="left_shoulder_psi_link"/>
    <child link="arm_l_upper"/>
    <origin rpy="0 0.68 0" xyz="0 0.0 0.0"/>
    <axis xyz="0 1 0"/>
    <dynamics damping="0.005"/>
    <limit effort="100.0" lower="-2.0" upper="1.0" velocity="1.0"/>
  </joint>
  <!-- 2D joint left elbow -->
  <joint name="LElbowTheta" type="fixed">
    <parent link="arm_l_upper"/>
    <child link="left_elbow_psi_link"/>
    <origin rpy="0.0 -1.94  0.0" xyz="-0.35 0.0  0.0"/>
    <axis xyz="0 1 0"/>
    <dynamics damping="0.005"/>
    <limit effort="101.0" lower="-0.7" upper="2.0" velocity="1.0"/>
  </joint>
  <link name="left_elbow_psi_link">
    <inertial>
      <mass value="0.01"/>
      <origin rpy="0 0 0" xyz="0 0.0 0.0"/>
      <inertia ixx="0.000000167" ixy="0" ixz="0" iyy="0.000000167" iyz="0" izz="0.000000167"/>
    </inertial>
    <visual>
      <origin rpy="0 0 0" xyz="0.0 0.0 0.0"/>
      <geometry>
        <box size="0.01 0.01 0.01"/>
      </geometry>
    </visual>
  </link>
  <joint name="elbow_left" type="fixed">
    <parent link="left_elbow_psi_link"/>
    <child link="arm_l_lower_1"/>
    <origin rpy="0 0 -0.09" xyz="0 0.0 0.0"/>
    <dynamics damping="0.005"/>
    <axis xyz="0 0 1"/>
    <limit effort="101.0" lower="-1.0" upper="1.0" velocity="1.0"/>
  </joint>
  <!-- hoe kom ik aan de andere kant van arm_lower_1 en 2 ?  -->
  <joint name="dummy_1" type="fixed">
    <parent link="arm_l_lower_1"/>
    <child link="dummy_link_1"/>
    <origin rpy="0 0 0.0" xyz="-0.2 0.0 0.0"/>
    <dynamics damping="0.005"/>
    <limit effort="101.0" lower="-1.0" upper="1.0" velocity="1.0"/>
  </joint>
  <link name="dummy_link_1">
    <inertial>
      <mass value="0.01"/>
      <origin rpy="0 0 0" xyz="0 0.0 0.0"/>
      <inertia ixx="0.000000167" ixy="0" ixz="0" iyy="0.000000167" iyz="0" izz="0.000000167"/>
    </inertial>
    <visual>
      <origin rpy="0 0 0" xyz="0.0 0.0 0.0"/>
      <geometry>
        <box size="0.01 0.01 0.01"/>
      </geometry>
    </visual>
  </link>
  <!-- Boat links -->
  <link name="world"/>
  <!-- Rower links -->
  <link name="footplate">
    <inertial>
      <mass value="0.1"/>
      <origin rpy="0 0 0" xyz="0 0.0 0.0"/>
      <inertia ixx="0.0008" ixy="0" ixz="0" iyy="0.000166" iyz="0" izz="0.0008"/>
    </inertial>
    <collision>
      <origin rpy="0 0 0" xyz="0 0.0   0.0"/>
      <geometry>
        <box size="0.1 0.3 0.1"/>
      </geometry>
    </collision>
    <visual>
      <origin rpy="0 0 0" xyz="0  0.0   0.0"/>
      <geometry>
        <box size="0.1 0.3 0.1"/>
      </geometry>
    </visual>
  </link>
  <link name="lowerleg">
    <inertial>
      <mass value="1.0"/>
      <origin rpy="0 0 0" xyz="-0.25 0.0 0.0"/>
      <inertia ixx="0.001" ixy="0" ixz="0" iyy="0.0005" iyz="0" izz="0.001"/>
    </inertial>
    <collision>
      <origin rpy="0 0 0" xyz="-0.25 0.0   0.0"/>
      <geometry>
        <box size="0.5 0.05 0.05"/>
      </geometry>
    </collision>
    <visual>
      <origin rpy="0 0 0" xyz="-0.25 0.0   0.0"/>
      <geometry>
        <box size="0.5 0.05 0.05"/>
      </geometry>
    </visual>
  </link>
  <!-- upperleg split into two parts to avoid a kinematic loop in the urdf
       the loop will be close in gazebo -->
  <link name="upperleg_1">
    <inertial>
      <mass value="1.0"/>
      <origin rpy="0 0 0" xyz="-0.125 0.0 0.0"/>
      <inertia ixx="0.001" ixy="0" ixz="0" iyy="0.0005" iyz="0" izz="0.001"/>
    </inertial>
    <collision>
      <origin rpy="0 0 0" xyz="-0.125  0.0   0.0"/>
      <geometry>
        <box size="0.25 0.05 0.05"/>
      </geometry>
    </collision>
    <visual>
      <origin rpy="0 0 0" xyz="-0.125   0.0   0.0"/>
      <geometry>
        <box size="0.25 0.05 0.05"/>
      </geometry>
    </visual>
  </link>
  <link name="upperleg_2">
    <inertial>
      <mass value="1.0"/>
      <origin rpy="0 0 0" xyz="0.125 0.0 0.0"/>
      <inertia ixx="0.001" ixy="0" ixz="0" iyy="0.0005" iyz="0" izz="0.001"/>
    </inertial>
    <collision>
      <origin rpy="0 0 0" xyz="0.125.  0.0   0.0"/>
      <geometry>
        <box size="0.25 0.05 0.05"/>
      </geometry>
    </collision>
    <visual>
      <origin rpy="0 0 0" xyz="0.125 0.0   0.0"/>
      <geometry>
        <box size="0.25 0.05 0.05"/>
      </geometry>
    </visual>
  </link>
  <link name="seat">
    <inertial>
      <mass value="0.1"/>
      <origin rpy="0 0 0" xyz="0.0 0.0 0.0"/>
      <inertia ixx="0.001" ixy="0" ixz="0" iyy="0.0005" iyz="0" izz="0.001"/>
    </inertial>
    <collision>
      <origin rpy="0 0 0" xyz="0.0 0.0   0.0"/>
      <geometry>
        <box size="0.1 0.3 0.1"/>
      </geometry>
    </collision>
    <visual>
      <origin rpy="0 0 0" xyz="0.0 0.0   0.0"/>
      <geometry>
        <box size="0.1 0.3 0.1"/>
      </geometry>
    </visual>
  </link>
  <link name="back_low">
    <inertial>
      <mass value="10.0"/>
      <origin rpy="0 0 0" xyz="0.15 0.0 0.0"/>
      <inertia ixx="0.01" ixy="0" ixz="0" iyy="0.077" iyz="0" izz="0.083"/>
    </inertial>
    <collision>
      <origin rpy="0 0 0" xyz="0.15.  0.0   0.0"/>
      <geometry>
        <box size="0.3 0.1 0.05"/>
      </geometry>
    </collision>
    <visual>
      <origin rpy="0 0 0" xyz="0.15 0.0   0.0"/>
      <geometry>
        <box size="0.3 0.1 0.05"/>
      </geometry>
    </visual>
  </link>
  <link name="back_high">
    <inertial>
      <mass value="10.0"/>
      <origin rpy="0 0 0" xyz="0.15 0.0 0.0"/>
      <inertia ixx="0.02" ixy="0" ixz="0" iyy="0.077" iyz="0" izz="0.094"/>
    </inertial>
    <collision>
      <origin rpy="0 0 0" xyz="0.15.  0.0   0.0"/>
      <geometry>
        <box size="0.3 0.15 0.05"/>
      </geometry>
    </collision>
    <visual>
      <origin rpy="0 0 0" xyz="0.15 0.0   0.0"/>
      <geometry>
        <box size="0.3 0.15 0.05"/>
      </geometry>
    </visual>
  </link>
  <link name="shoulder_link">
    <inertial>
      <mass value="1.0"/>
      <origin rpy="0 0 0" xyz="0.0 0.0 0.0"/>
      <inertia ixx="0.013" ixy="0" ixz="0" iyy="0.0004" iyz="0" izz="0.013"/>
    </inertial>
    <visual>
      <origin rpy="0 0 0" xyz="0.0 0.0   0.0"/>
      <geometry>
        <box size="0.05 0.4 0.05"/>
      </geometry>
    </visual>
  </link>
  <link name="arm_l_upper">
    <inertial>
      <mass value="1.0"/>
      <origin rpy="0 0 0" xyz="-0.175 0.0 0.0"/>
      <inertia ixx="0.004" ixy="0" ixz="0" iyy="0.01" iyz="0" izz="0.01"/>
    </inertial>
    <visual>
      <origin rpy="0 0 0" xyz="-0.175 0.0   0.0"/>
      <geometry>
        <box size="0.35 0.05 0.05"/>
      </geometry>
    </visual>
  </link>
  <!-- lower arm in two to create a kinematic loop in gazebo -->
  <link name="arm_l_lower_1">
    <inertial>
      <mass value="1.0"/>
      <origin rpy="0 0 0" xyz="-0.1 0.0 0.0"/>
      <inertia ixx="0.0004" ixy="0" ixz="0" iyy="0.0035" iyz="0" izz="0.0035"/>
    </inertial>
    <visual>
      <origin rpy="0 0 0" xyz="-0.1 0.0   0.0"/>
      <geometry>
        <box size="0.20 0.05 0.05"/>
      </geometry>
    </visual>
  </link>
  <!-- Boat transmissions -->
  <transmission name="tran7">
    <type>transmission_interface/SimpleTransmission</type>
    <joint name="knee">
      <hardwareInterface>hardware_interface/EffortJointInterface</hardwareInterface>
    </joint>
    <actuator name="motor7">
      <mechanicalReduction>1</mechanicalReduction>
    </actuator>
  </transmission>
  <transmission name="tran8">
    <type>transmission_interface/SimpleTransmission</type>
    <joint name="hip1">
      <hardwareInterface>hardware_interface/EffortJointInterface</hardwareInterface>
    </joint>
    <actuator name="motor8">
      <mechanicalReduction>1</mechanicalReduction>
    </actuator>
  </transmission>
  <transmission name="tran9">
    <type>transmission_interface/SimpleTransmission</type>
    <joint name="hip2">
      <hardwareInterface>hardware_interface/EffortJointInterface</hardwareInterface>
    </joint>
    <actuator name="motor9">
      <mechanicalReduction>1</mechanicalReduction>
    </actuator>
  </transmission>
  <transmission name="tran10">
    <type>transmission_interface/SimpleTransmission</type>
    <joint name="back_lh">
      <hardwareInterface>hardware_interface/EffortJointInterface</hardwareInterface>
    </joint>
    <actuator name="motor10">
      <mechanicalReduction>1</mechanicalReduction>
    </actuator>
  </transmission>
  <transmission name="tran11">
    <type>transmission_interface/SimpleTransmission</type>
    <joint name="shoulder_l">
      <hardwareInterface>hardware_interface/EffortJointInterface</hardwareInterface>
    </joint>
    <actuator name="motor11">
      <mechanicalReduction>1</mechanicalReduction>
    </actuator>
  </transmission>
  <!--
  <transmission name="tran12">
    <type>transmission_interface/SimpleTransmission</type>
    <joint name="shoulder_iets">
      <hardwareInterface>hardware_interface/EffortJointInterface</hardwareInterface>
    </joint>
    <actuator name="motor12">
      <mechanicalReduction>1</mechanicalReduction>
    </actuator>
  </transmission>
-->
  <transmission name="tran13">
    <type>transmission_interface/SimpleTransmission</type>
    <joint name="LShoulderTheta">
      <hardwareInterface>hardware_interface/EffortJointInterface</hardwareInterface>
    </joint>
    <actuator name="motor13">
      <mechanicalReduction>1</mechanicalReduction>
    </actuator>
  </transmission>
</robot>

